<?xml version="1.0"?>

<robot name="lisa">
	<link name="world"/>

    <joint name="base_joint" type="fixed">
    		<parent link="world"/>
    		<child link="base_link"/>
    		<origin xyz="0 0 0" rpy="0 0 0" />
  	</joint>

	<link name="base_link">
   		<inertial>
      		<origin xyz="0.0 0.0 0.0" rpy="0 0 0"/>
      		<mass value="0.0"/>
      		<inertia ixx="0.0" ixy="0.0" ixz="0.0" iyy="0.0" iyz="0.0" izz="0.0"/>
    	</inertial>
		
		<visual>
			<geometry>
				<mesh filename = "package://elissa3_homer/lisa_parts/Basis_3.stl" scale="0.01 0.01 0.01"/> <!--scale from mm to m should be 0.001--> <!--scale="0.01 0.01 0.01"--> 
			</geometry>
				
			<!--origin - the reference frame of the visual element with respect to the reference frame of the link -->
			<!--rpy -r is roll, p-pitch and y-yaw (Eulerwinkel) -->
			<!--xyz - x,y,z -offsets -->
			<origin xyz="0 0 0" rpy="0 0 0" />
			<material name="yellow">
				<color rgba="1 1 0 1"/>
			</material>
		</visual>
		
    	<collision>
      		<origin xyz="0.0 0.0 0.0" rpy="0 0 0"/>
      		<geometry>
        		<mesh filename = "package://elissa3_homer/lisa_parts/Basis_3.stl" scale="0.01 0.01 0.01"/>
      		</geometry>
    	</collision>	
	</link>

	<joint name="joint_1" type="revolute"> <!-- maybe continous -->
		<parent link="base_link"/>
		<child link="link_1"/>
		<origin xyz="0 0 0.25" rpy="0 -0.7854 0"/>
		<axis xyz="0 0 1"/>
		<limit effort="300" velocity="2.0" lower="-6" upper="6"/>
		<dynamics damping="0.1"/>
	</joint>
	
	<link name="link_1">
		<inertial>
      		<origin xyz="0.0 0 0.0" rpy="0 0 0" />
      		<mass value="0.0"/>
      		<inertia ixx="0.0" ixy="0.0" ixz="0.0" iyy="0.0" iyz="0.0" izz="0.0"/>
    	</inertial>
    		
		<visual>
			<geometry>
				<mesh filename = "package://elissa3_homer/lisa_parts/Glied_3_NeuX.stl" scale="0.01 0.01 0.01"/> <!--scale="0.01 0.01 0.01"--> 
			</geometry>
			<origin xyz="0.0 0 0" rpy="0 0 0" />
			<material name="blue">
				<color rgba="0 0 1 1"/>
			</material>
		</visual>
		<collision>
      		<origin xyz="0.0 0 0.0" rpy="0 0 0" />
      		<geometry>
        		<mesh filename = "package://elissa3_homer/lisa_parts/Glied_3.stl" scale="0.01 0.01 0.01"/> <!--scale="0.01 0.01 0.01"-->
      		</geometry>
    	</collision>
 	</link>
	
	<joint name="joint_2" type="revolute"> <!-- maybe continous -->
		<parent link="link_1"/>
		<child link="link_2"/>
		<origin xyz="0.35355 0 0.35355" rpy="0 1.5708 0"/>
		<axis xyz="0 0 1"/>
		<limit effort="300" velocity="2.0" lower="-6" upper="6"/>
		<dynamics damping="0.1"/>
	</joint>

	<link name="link_2">
		<inertial>
      		<origin xyz="0.0 0 0.0" rpy="0 0 0" />
      		<mass value="0.0"/>
      		<inertia ixx="0.0" ixy="0.0" ixz="0.0" iyy="0.0" iyz="0.0" izz="0.0"/>
    	</inertial>
    		
		<visual>
			<geometry>
				<mesh filename = "package://elissa3_homer/lisa_parts/Glied_3_NeuX.stl" scale="0.01 0.01 0.01"/> <!--scale="0.01 0.01 0.01"--> 
			</geometry>
			<origin xyz="0.0 0 0" rpy="0 0 3.1416" />
			<material name="yellow">
				<color rgba="1 1 0 1"/>
			</material>
		</visual>
		<collision>
      		<origin xyz="0.0 0 0.0" rpy="0 0 0" />
      		<geometry>
        		<mesh filename = "package://elissa3_homer/lisa_parts/Glied_3.stl" scale="0.01 0.01 0.01"/> <!--scale="0.01 0.01 0.01"-->
      		</geometry>
    	</collision>
 	</link>

	<joint name="joint_3" type="revolute"> <!-- maybe continous -->
		<parent link="link_2"/>
		<child link="link_3"/>
		<origin xyz="-0.35355 0 0.35355" rpy="0 -1.5708  0"/>
		<axis xyz="0 0 1"/>
		<limit effort="300" velocity="2.0" lower="-6" upper="6"/>
		<dynamics damping="0.1"/>
	</joint>

	<link name="link_3">
		<inertial>
      		<origin xyz="0.0 0 0.0" rpy="0 0 0" />
      		<mass value="0.0"/>
      		<inertia ixx="0.0" ixy="0.0" ixz="0.0" iyy="0.0" iyz="0.0" izz="0.0"/>
    	</inertial>
    		
		<visual>
			<geometry>
				<mesh filename = "package://elissa3_homer/lisa_parts/Glied_3_NeuX.stl" scale="0.01 0.01 0.01"/> <!--scale="0.01 0.01 0.01"--> 
			</geometry>
			<origin xyz="0.0 0 0" rpy="0 0 0" />
			<material name="blue">
				<color rgba="0 0 1 1"/>
			</material>
		</visual>
		<collision>
      		<origin xyz="0.0 0 0.0" rpy="0 0 0" />
      		<geometry>
        		<mesh filename = "package://elissa3_homer/lisa_parts/Glied_3.stl" scale="0.01 0.01 0.01"/> <!--scale="0.01 0.01 0.01"-->
      		</geometry>
    	</collision>

	</link>

	<joint name="joint_4" type="revolute"> <!-- maybe continous -->
		<parent link="link_3"/>
		<child link="link_4"/>
		<origin xyz="0.35355 0 0.35355" rpy="0 1.5708 0"/>
		<axis xyz="0 0 1"/>
		<limit effort="300" velocity="2.0" lower="-6" upper="6"/>
		<dynamics damping="0.1"/>
	</joint>
	
	<link name="link_4">
		<inertial>
      		<origin xyz="0.0 0 0.0" rpy="0 0 0" />
      		<mass value="0.0"/>
      		<inertia ixx="0.0" ixy="0.0" ixz="0.0" iyy="0.0" iyz="0.0" izz="0.0"/>
    	</inertial>
    		
		<visual>
			<geometry>
				<mesh filename = "package://elissa3_homer/lisa_parts/Glied_3_NeuX.stl" scale="0.01 0.01 0.01"/> <!--scale="0.01 0.01 0.01"--> 
			</geometry>
			<origin xyz="0.0 0 0" rpy="0 0  3.1416" />
			<material name="yellow">
				<color rgba="0 0 1 1"/>
			</material>
		</visual>
		<collision>
      		<origin xyz="0.0 0 0.0" rpy="0 0 0" />
      		<geometry>
        		<mesh filename = "package://elissa3_homer/lisa_parts/Glied_3.stl" scale="0.01 0.01 0.01"/> <!--scale="0.01 0.01 0.01"-->
      		</geometry>
    	</collision>
 	</link>

	<joint name="joint_5" type="revolute"> <!-- maybe continous -->
		<parent link="link_4"/>
		<child link="link_5"/>
		<origin xyz="-0.35355 0 0.35355" rpy="0 -1.5708 0"/>
		<axis xyz="0 0 1"/>
		<limit effort="300" velocity="2.0" lower="-6" upper="6"/>
		<dynamics damping="0.1"/>3.1416
	</joint>

	<link name="link_5">
		<inertial>
      		<origin xyz="0.0 0 0.0" rpy="0 0 0" />
      		<mass value="0.0"/>
      		<inertia ixx="0.0" ixy="0.0" ixz="0.0" iyy="0.0" iyz="0.0" izz="0.0"/>
    	</inertial>
    		
		<visual>
			<geometry>
				<mesh filename = "package://elissa3_homer/lisa_parts/Glied_3_NeuX.stl" scale="0.01 0.01 0.01"/> <!--scale="0.01 0.01 0.01"--> 
			</geometry>
			<origin xyz="0.0 0 0" rpy="0 0  0" />
			<material name="blue">
				<color rgba="0 0 1 1"/>
			</material>
		</visual>
		<collision>
      		<origin xyz="0.0 0 0.0" rpy="0 0 0" />
      		<geometry>
        		<mesh filename = "package://elissa3_homer/lisa_parts/Glied_3.stl" scale="0.01 0.01 0.01"/> <!--scale="0.01 0.01 0.01"-->
      		</geometry>
    	</collision>
 	</link>

	<joint name="joint_6" type="revolute"> <!-- maybe continous -->
		<parent link="link_5"/>
		<child link="link_6"/>
		<origin xyz="0.35355 0 0.35355" rpy="0 1.5708 0"/>
		<axis xyz="0 0 1"/>
		<limit effort="300" velocity="2.0" lower="-6" upper="6"/>
		<dynamics damping="0.1"/>
	</joint>

	<link name="link_6">
		<inertial>
      		<origin xyz="0.0 0 0.0" rpy="0 0 0" />
      		<mass value="0.0"/>
      		<inertia ixx="0.0" ixy="0.0" ixz="0.0" iyy="0.0" iyz="0.0" izz="0.0"/>
    	</inertial>
    		
		<visual>
			<geometry>
				<mesh filename = "package://elissa3_homer/lisa_parts/Glied_3_NeuX.stl" scale="0.01 0.01 0.01"/> <!--scale="0.01 0.01 0.01"--> 
			</geometry>
			<origin xyz="0.0 0 0" rpy="0 0 3.1416" />
			<material name="yellow">
				<color rgba="0 0 1 1"/>
			</material>
		</visual>
		<collision>
      		<origin xyz="0.0 0 0.0" rpy="0 0 0" />
      		<geometry>
        		<mesh filename = "package://elissa3_homer/lisa_parts/Glied_3.stl" scale="0.01 0.01 0.01"/> <!--scale="0.01 0.01 0.01"-->
      		</geometry>
    	</collision>
 	</link>

	<joint name="joint_7" type="revolute"> <!-- maybe continous -->
		<parent link="link_6"/>
		<child link="link_7"/>
		<origin xyz="-0.35355 0 0.35355" rpy="0 -1.5708 0"/>
		<axis xyz="0 0 1"/>
		<limit effort="300" velocity="2.0" lower="-6" upper="6"/>
		<dynamics damping="0.1"/>
	</joint>

	<link name="link_7">
		<inertial>
      		<origin xyz="0.0 0 0.0" rpy="0 0 0" />
      		<mass value="0.0"/>
      		<inertia ixx="0.0" ixy="0.0" ixz="0.0" iyy="0.0" iyz="0.0" izz="0.0"/>
    	</inertial>
    		
		<visual>
			<geometry>
				<mesh filename = "package://elissa3_homer/lisa_parts/Glied_3_NeuX.stl" scale="0.01 0.01 0.01"/> <!--scale="0.01 0.01 0.01"--> 
			</geometry>
			<origin xyz="0.0 0 0" rpy="0 0  0" />
			<material name="blue">
				<color rgba="0 0 1 1"/>
			</material>
		</visual>
		<collision>
      		<origin xyz="0.0 0 0.0" rpy="0 0 0" />
      		<geometry>
        		<mesh filename = "package://elissa3_homer/lisa_parts/Glied_3.stl" scale="0.01 0.01 0.01"/> <!--scale="0.01 0.01 0.01"-->
      		</geometry>
    	</collision>
 	</link>

	<joint name="joint_8" type="revolute"> <!-- maybe continous -->
		<parent link="link_7"/>
		<child link="link_8"/>
		<origin xyz="0.35355 0 0.35355" rpy="0 1.5708 0"/>
		<axis xyz="0 0 1"/>
		<limit effort="300" velocity="2.0" lower="-6" upper="6"/>
		<dynamics damping="0.1"/>
	</joint>

	<link name="link_8">
		<inertial>
      		<origin xyz="0.0 0 0.0" rpy="0 0 0" />
      		<mass value="0.0"/>
      		<inertia ixx="0.0" ixy="0.0" ixz="0.0" iyy="0.0" iyz="0.0" izz="0.0"/>
    	</inertial>
    		
		<visual>
			<geometry>
				<mesh filename = "package://elissa3_homer/lisa_parts/Glied_3_NeuX.stl" scale="0.01 0.01 0.01"/> <!--scale="0.01 0.01 0.01"--> 
			</geometry>
			<origin xyz="0.0 0 0" rpy="0 0 3.1416" />
			<material name="yellow">
				<color rgba="0 0 1 1"/>
			</material>
		</visual>
		<collision>
      		<origin xyz="0.0 0 0.0" rpy="0 0 0" />
      		<geometry>
        		<mesh filename = "package://elissa3_homer/lisa_parts/Glied_3.stl" scale="0.01 0.01 0.01"/> <!--scale="0.01 0.01 0.01"-->
      		</geometry>
    	</collision>
 	</link>


</robot> 